Traceback (most recent call last):
  File "/home/dahn017/courses/cs260/CS260-MMA/src/main.py", line 55, in <module>
    main()
  File "/home/dahn017/courses/cs260/CS260-MMA/src/main.py", line 51, in main
    results = train(dataset, config)
  File "/home/dahn017/courses/cs260/CS260-MMA/src/train.py", line 64, in train
    train_result = pt_evaluate(loss, pred)
  File "/home/dahn017/courses/cs260/CS260-MMA/src/clf.py", line 36, in pt_evaluate
    acc = tmf.accuracy(pred, true, task=task)
  File "/home/dahn017/miniconda3/envs/tensor/lib/python3.9/site-packages/torchmetrics/functional/classification/accuracy.py", line 423, in accuracy
    return binary_accuracy(preds, target, threshold, multidim_average, ignore_index, validate_args)
  File "/home/dahn017/miniconda3/envs/tensor/lib/python3.9/site-packages/torchmetrics/functional/classification/accuracy.py", line 160, in binary_accuracy
    _binary_stat_scores_tensor_validation(preds, target, multidim_average, ignore_index)
  File "/home/dahn017/miniconda3/envs/tensor/lib/python3.9/site-packages/torchmetrics/functional/classification/stat_scores.py", line 61, in _binary_stat_scores_tensor_validation
    _check_same_shape(preds, target)
  File "/home/dahn017/miniconda3/envs/tensor/lib/python3.9/site-packages/torchmetrics/utilities/checks.py", line 35, in _check_same_shape
    raise RuntimeError(
RuntimeError: Predictions and targets are expected to have the same shape, but got torch.Size([]) and torch.Size([64, 1]).